<?xml version="1.0"?>
<robot name="tor" xmlns:xacro="http://ros.org/wiki/xacro" >

   <xacro:include filename="$(find tor_description)/urdf/leg/leg.transmission.xacro" />
   <xacro:property name="leg_reduction"      value="1.0" />
   <xacro:property name="leg_friction"       value="0.0" />
   <xacro:property name="leg_damping"        value="0.0" />

   <xacro:macro name="tor_leg" params="prefix reflect">
  
    <link name="leg_${prefix}_1_link">
      <inertial>
        <origin xyz="0.033   0.0   -0.112" rpy="0 0 0"/>
        <mass value="1.3" />
         <inertia ixx="0.003"  ixy="0.0"  ixz="0.0" iyy="0.004" iyz="0.0" izz="0.002" />
      </inertial>
    
      <visual>
        <origin rpy="0 0 3.14" xyz="0 0 0"/>
        <geometry>
          <mesh filename="package://tor_description/meshes/hipZ.STL" scale="1 ${reflect*1} 1"/>
        </geometry>
        <!-- <material name="LightGrey" /> -->
      </visual>
      
      <collision>
        <origin rpy="0 0 0" xyz="0 0 -0.02"/>
	    <geometry>
           <box size="0.1 0.1 0.1"/>
        </geometry>
      </collision>  
      
    </link>

    <link name="leg_${prefix}_2_link">
      <inertial>
        <origin xyz="0.0 0.0 0.0" rpy="0 0 0"/>
        <mass value="1.2" />
         <inertia ixx="0.001"  ixy="0.0"  ixz="0.0" iyy="0.001" iyz="0.0" izz="0.001" />
      </inertial>

      <visual>
        <origin xyz="0 0 0.0" rpy="1.57  0  0" />
        <geometry>
          <cylinder radius="0.05" length="0.15"/>
        </geometry>
        <material name="DarkGrey" />
      </visual>

      <collision>
	    <origin xyz="0 0 0.0" rpy="1.57  0  0" />
        <geometry>
          <cylinder radius="0.05" length="0.15"/>
        </geometry>
      </collision>  

     </link>
  
    <link name="leg_${prefix}_3_link">
      <visual>
        <origin rpy="0 0 0" xyz="0 0 0"/>
        <geometry>
          <mesh filename="package://tor_description/meshes/femur.STL" scale="1 ${reflect*1} 1"/>
        </geometry>
        <!-- <material name="LightGrey" /> -->
      </visual>

      <collision>
		<origin rpy="0 0 0" xyz="0 0 -0.2"/>
        <geometry>
           <box size="0.1 0.15 0.25"/>
        </geometry>
      </collision>  

      <inertial>
        <origin xyz="0.005 ${reflect*0.057} -0.195" rpy="0 0 0"/>
        <mass value="6.4" />
         <inertia ixx="0.117"  ixy="${reflect*-0.001}"  ixz="0.001" iyy="0.106" iyz="${reflect*0.018}" izz="0.021" />
      </inertial>
     </link>

    <link name="leg_${prefix}_4_link">
		
      <inertial>
        <origin xyz="0.008 ${reflect*0.033} -0.139" rpy="0 0 0"/>
        <mass value="3.6" />
         <inertia ixx="0.033"  ixy="${reflect*-0.001}"  ixz="0.001" iyy="0.028" iyz="0.0" izz="0.011" />
      </inertial>
      
     <visual>
        <origin rpy="0 0 0" xyz="0 0 0"/>
        <geometry>
          <mesh filename="package://tor_description/meshes/tibia.STL" scale="1 ${reflect*1} 1"/>
        </geometry>
        <!-- <material name="LightGrey" /> -->
      </visual>

      <collision>
	    <origin rpy="0 0 0" xyz="0 0 -0.175"/>
        <geometry>
           <box size="0.1 0.15 0.3"/>
        </geometry>
      </collision>  
      
     </link>

    <link name="leg_${prefix}_5_link">
		
      <inertial>
        <origin xyz="-0.003 ${reflect*0.007} -0.005" rpy="0 0 0"/>
        <mass value="1.1" />
         <inertia ixx="0.001"  ixy="0.0"  ixz="0.0" iyy="0.001" iyz="0.0" izz="0.001" />
      </inertial>
      
      <visual>
        <origin xyz="0 0 0.0" rpy="1.57 0 0" />
       <geometry>
          <cylinder radius="0.01" length="0.14"/>
        </geometry>
        <material name="Grey" />
      </visual>
      
      <collision>
	   <origin xyz="0 0 0.0" rpy="1.57 0 0" />
       <geometry>
          <cylinder radius="0.01" length="0.14"/>
        </geometry>
      </collision>  
      
     </link>
     
     <link name="leg_${prefix}_6_link">
      <inertial>
        <origin xyz="-0.008 0.0 -0.097" rpy="0 0 0"/>
        <mass value="0.9" />
         <inertia ixx="0.002"  ixy="0.0"  ixz="0.0" iyy="0.001" iyz="0.0" izz="0.001" />
      </inertial>
      <visual>
        <origin rpy="0 0 0" xyz="0 0 0"/>
        <geometry>
          <mesh filename="package://tor_description/meshes/foot.STL" scale="1 ${reflect*1} 1"/>
        </geometry>
        <!-- <material name="LightGrey" /> -->
      </visual>
      <collision>
        <origin xyz="0 0 -0.1" rpy="0 0 0" />
        <geometry>
           <box size="0.21 0.13 0.02"/>
        </geometry>
      </collision> 

     </link>
     
     
    <link name="${prefix}_sole_link">
      <inertial>
        <origin xyz="0.0 0.0 0.0" rpy="0 0 0"/>
        <mass value="0.01" />
         <inertia ixx="0.0001"  ixy="0.0"  ixz="0.0" iyy="0.0001" iyz="0.0" izz="0.0001" />
      </inertial>
     </link> 

    <joint name="leg_${prefix}_1_joint" type="revolute">
      <parent link="base_link" />
      <child link="leg_${prefix}_1_link" />
      <origin xyz="0.0 ${reflect*0.08} 0.0" rpy="0 0 0" />
      <axis xyz="0 0 1" />
      <!-- nominal -->
      <!-- <limit lower="-0.5236" upper="1.571" effort="49" velocity="3.87" /> -->
      <!-- peak -->   
      <xacro:if value="${reflect == 1}">
        <limit lower="-0.5236" upper="1.571" effort="100" velocity="3.87" />
      </xacro:if>
      <xacro:if value="${reflect == -1}">
        <limit lower="-1.571" upper="0.5236" effort="100" velocity="3.87" />
      </xacro:if>
      <dynamics friction="${leg_friction}" damping="${leg_damping}"/>
     </joint>

   <joint name="leg_${prefix}_2_joint" type="revolute">
      <parent link="leg_${prefix}_1_link" />
      <child link="leg_${prefix}_2_link" />
      <origin xyz="0.0 0.0 -0.10" rpy="0 0 0" />
      <axis xyz="1 0 0" />
      <!-- nominal -->
      <!-- <limit lower="-0.524" upper="0.5236" effort="90" velocity="5.8" /> -->
      <!--peak -->
      <limit lower="-0.524" upper="0.5236" effort="160" velocity="5.8" />
      <dynamics friction="${leg_friction}" damping="${leg_damping}"/>
     </joint>

    <joint name="leg_${prefix}_3_joint" type="revolute">
      <parent link="leg_${prefix}_2_link" />
      <child link="leg_${prefix}_3_link" />
      <origin xyz="0.0 0.0 -0.0" rpy="0 0 0" />
      <axis xyz="0 1 0" />
      <!-- nomial -->
      <!-- <limit lower="-2.095" upper="0.7" effort="90" velocity="5.8" /> -->
      <!-- peak -->
      <limit lower="-2.095" upper="0.7" effort="160" velocity="5.8" />
      <dynamics friction="${leg_friction}" damping="${leg_damping}"/>
     </joint>
   
   
    <joint name="leg_${prefix}_4_joint" type="revolute">
      <parent link="leg_${prefix}_3_link" />
      <child link="leg_${prefix}_4_link" />
      <origin xyz="0.00 -0.0 -0.38" rpy="0 0 0" />
      <axis xyz="0 1 0" />
      <!-- nominal -->
      <!-- <limit lower="0" upper="2.618" effort="145" velocity="7" /> -->
      <!-- peak -->
      <limit lower="0" upper="2.618" effort="300" velocity="7" />
      <dynamics friction="${leg_friction}" damping="${leg_damping}"/>
     </joint>
  
     
    <joint name="leg_${prefix}_5_joint" type="revolute">
      <parent link="leg_${prefix}_4_link" />
      <child link="leg_${prefix}_5_link" />
      <origin xyz="0.00 0.00 -0.32" rpy="0 0 0" />
      <axis xyz="0 1 0" />
      <!-- nominal -->
      <!-- <limit lower="-1.309" upper="0.768" effort="90" velocity="5.8" /> -->
      <!-- peak -->
      <limit lower="-1.309" upper="0.768" effort="160" velocity="5.8" />
      <dynamics friction="${leg_friction}" damping="${leg_damping}"/>
     </joint>
     
    <joint name="leg_${prefix}_6_joint" type="revolute">
      <parent link="leg_${prefix}_5_link" />
      <child link="leg_${prefix}_6_link" />
      <origin xyz="0.00 0.00 -0.0" rpy="0 0 0" />
      <axis xyz="1 0 0" />
      <!-- nominal -->
      <!-- <limit lower="-0.524" upper="0.524" effort="62" velocity="4.8" /> -->
      <!-- peak -->
      <limit lower="-0.524" upper="0.524" effort="100" velocity="4.8" />
    </joint>
    
   
     <joint name="leg_${prefix}_sole_fix_joint" type="fixed">
      <parent link="leg_${prefix}_6_link" />
      <child link="${prefix}_sole_link" />
      <origin xyz="0.00 0.00 -0.107" rpy="0 0 0" />
      <axis xyz="1 0 0" />
      <dynamics friction="${leg_friction}" damping="${leg_damping}"/>
    </joint> 
    
    <xacro:tor_leg_simple_transmission side="${prefix}" number="1" reduction="${leg_reduction}" />
    <xacro:tor_leg_simple_transmission side="${prefix}" number="2" reduction="${leg_reduction}" />
    <xacro:tor_leg_simple_transmission side="${prefix}" number="3" reduction="${leg_reduction}" />
    <xacro:tor_leg_simple_transmission side="${prefix}" number="4" reduction="${leg_reduction}" />
    <xacro:tor_leg_simple_transmission side="${prefix}" number="5" reduction="${leg_reduction}" />
    <xacro:tor_leg_simple_transmission side="${prefix}" number="6" reduction="${leg_reduction}" />
    
   <gazebo reference="leg_${prefix}_1_link">
     <mu1>0.9</mu1>
     <mu2>0.9</mu2>
   </gazebo>
   <gazebo reference="leg_${prefix}_2_link">
     <mu1>0.9</mu1>
     <mu2>0.9</mu2>
   </gazebo>
   <gazebo reference="leg_${prefix}_3_link">
     <mu1>0.9</mu1>
     <mu2>0.9</mu2>
   </gazebo>
   <gazebo reference="leg_${prefix}_4_link">
     <mu1>0.9</mu1>
     <mu2>0.9</mu2>
   </gazebo>
   <gazebo reference="leg_${prefix}_5_link">
     <mu1>0.9</mu1>
     <mu2>0.9</mu2>
   </gazebo>
   
   <!-- contact model for foot surface -->
   <gazebo reference="leg_${prefix}_6_link">
     <kp>1000000.0</kp>
     <kd>100.0</kd>
     <mu1>1.0</mu1>
     <mu2>1.0</mu2>
     <fdir1>0 0 1</fdir1>
     <maxVel>1.0</maxVel>
     <minDepth>0.003</minDepth>
     <implicitSpringDamper>1</implicitSpringDamper>
   </gazebo>

   <gazebo reference="leg_${prefix}_1_joint">
      <implicitSpringDamper>0.1</implicitSpringDamper>
   </gazebo>
   <gazebo reference="leg_${prefix}_2_joint">
      <implicitSpringDamper>0.1</implicitSpringDamper>
   </gazebo>
   <gazebo reference="leg_${prefix}_3_joint">
      <implicitSpringDamper>0.1</implicitSpringDamper>
   </gazebo>
   <gazebo reference="leg_${prefix}_4_joint">
      <implicitSpringDamper>0.1</implicitSpringDamper>
   </gazebo>
   <gazebo reference="leg_${prefix}_5_joint">
      <implicitSpringDamper>0.1</implicitSpringDamper>
   </gazebo>
   <gazebo reference="leg_${prefix}_6_joint">
     <implicitSpringDamper>0.1</implicitSpringDamper>
     <provideFeedback>1</provideFeedback>
   </gazebo>
        
 </xacro:macro>
   
   
</robot>
