<?xml version="1.0"?>
<!--

  Copyright (c) 2016, PAL Robotics, S.L.
  All rights reserved.

  This work is licensed under the Creative Commons Attribution-NonCommercial-NoDerivs 3.0 Unported License.
  To view a copy of this license, visit http://creativecommons.org/licenses/by-nc-nd/3.0/ or send a letter to
  Creative Commons, 444 Castro Street, Suite 900, Mountain View, California, 94041, USA.
-->
<robot xmlns:xacro="http://ros.org/wiki/xacro">

  <!--File includes-->
  <xacro:include filename="$(find talos_description)/urdf/deg_to_rad.xacro" />
  <xacro:include filename="$(find talos_description)/urdf/arm/wrist.transmission.xacro" />

  <!--Constant parameters-->
  <xacro:property name="wrist_friction"       value="1.0" />
  <xacro:property name="wrist_damping"        value="1.0" />
  <xacro:property name="wrist_1_max_vel"      value="1.95" />
  <xacro:property name="wrist_2_max_vel"      value="1.76" />
  <xacro:property name="wrist_3_max_vel"      value="1.76" />
  <xacro:property name="wrist_1_max_effort"   value="3" />
  <xacro:property name="wrist_2_max_effort"   value="6.6" />
  <xacro:property name="wrist_3_max_effort"   value="6.6" />
  <xacro:property name="wrist_eps"          value="0.02" />


  <xacro:macro name="talos_wrist" params="name parent side reflect">

    <!--************************-->
    <!--        WRIST           -->
    <!--************************-->
    <link name="${name}_${side}_5_link">
      <inertial>
        <origin xyz="-0.00006000000 ${reflect*0.00326200000} 0.07962500000" rpy="0.00000000000 0.00000000000 0.00000000000"/>
        <mass value="1.87792300000"/>
        <inertia ixx="0.00349507283" ixy="${reflect*0.00001265489}" ixz="0.00001038286"
                 iyy="0.00436830072" iyz="${reflect*-0.00009736042}"
                 izz="0.00228263370"/>
      </inertial>

      <visual>
        <origin xyz="0 0 0" rpy="0 0 0" />
        <geometry>
          <mesh filename="package://talos_description/meshes/arm/arm_5.STL" scale="1 ${reflect} 1"/>
        </geometry>
        <material name="LightGrey" />
      </visual>

      <collision>
        <origin xyz="0 0 0" rpy="0 0 0" />
        <geometry>
          <mesh filename="package://talos_description/meshes/arm/arm_5_collision.STL" scale="1 ${reflect} 1"/>
        </geometry>
      </collision>
    </link>

    <joint name="${name}_${side}_5_joint" type="revolute">
      <parent link="${parent}" />
      <child link="${name}_${side}_5_link" />
      <origin xyz="-0.02000 0.00000 -0.26430"
                rpy="${0.00000 * deg_to_rad} ${0.00000 * deg_to_rad} ${0.00000 * deg_to_rad}"/>
      <axis xyz="0 0 1" />
      <limit lower="${-144.0 * deg_to_rad}" upper="${144.0 * deg_to_rad}" effort="${wrist_1_max_effort}" velocity="${wrist_1_max_vel}" />
      <dynamics friction="${wrist_friction}" damping="${wrist_damping}"/>
<!--       <safety_controller k_position="20"
                          k_velocity="20"
                          soft_lower_limit="${-145.00000 * deg_to_rad + wrist_eps}"
                          soft_upper_limit="${145.00000 * deg_to_rad - wrist_eps}" /> -->

    </joint>

    <link name="${name}_${side}_6_link">
      <inertial>
        <origin xyz="0.00002100000 ${reflect*-0.00196500000} -0.00059100000" rpy="0.00000000000 0.00000000000 0.00000000000"/>
        <mass value="0.40931000000"/>
        <inertia ixx="0.00010700023" ixy="${reflect*-0.00000008899}" ixz="-0.00000004392"
                 iyy="0.00014101316" iyz="${reflect*0.00000041702}"
                 izz="0.00015398658"/>
      </inertial>

      <visual>
        <origin xyz="0 0 0" rpy="0 0 0" />
        <geometry>
          <mesh filename="package://talos_description/meshes/arm/arm_6.STL" scale="1 ${reflect} 1"/>
        </geometry>
        <material name="LightGrey" />
      </visual>

      <collision>
        <origin xyz="0 0 0" rpy="0 0 0" />
        <geometry>
          <mesh filename="package://talos_description/meshes/arm/arm_6_collision.STL" scale="1 ${reflect} 1"/>
        </geometry>
      </collision>
    </link>

    <joint name="${name}_${side}_6_joint" type="revolute">
      <parent link="${name}_${side}_5_link" />
      <child link="${name}_${side}_6_link" />
      <origin xyz="0.00000 0.00000 0.00000"
              rpy="${0.00000 * deg_to_rad} ${0.00000 * deg_to_rad} ${0.00000 * deg_to_rad}"/>
      <axis xyz="1 0 0" />
      <limit lower="${-78.5 * deg_to_rad}" upper="${78.5 * deg_to_rad}" effort="${wrist_2_max_effort}" velocity="${wrist_2_max_vel}" />
      <dynamics friction="${wrist_friction}" damping="${wrist_damping}"/>
<!--       <safety_controller k_position="20"
                          k_velocity="20"
                          soft_lower_limit="${-80.00000 * deg_to_rad + eps_radians}"
                          soft_upper_limit="${80.00000 * deg_to_rad - eps_radians}" /> -->

    </joint>

    <link name="${name}_${side}_7_link">
      <inertial>
        <origin xyz="0.00752500000 ${reflect*0.00137800000} -0.02463000000" rpy="0.00000000000 0.00000000000 0.00000000000"/>
        <mass value="0.30844100000"/>
        <inertia ixx="0.00030894317" ixy="${reflect*-0.00000158687}" ixz="0.00000173418"
                 iyy="0.00021886181" iyz="${reflect*-0.00001221167}"
                 izz="0.00017519492"/>
      </inertial>

      <visual>
        <origin xyz="0 0 0" rpy="0 0 0" />
        <geometry>
          <mesh filename="package://talos_description/meshes/arm/arm_7.STL" scale="1 ${reflect} 1"/>
        </geometry>
        <material name="DarkGrey" />
      </visual>

      <collision>
        <origin xyz="0 0 0" rpy="0 0 0" />
        <geometry>
          <mesh filename="package://talos_description/meshes/arm/arm_7_collision.STL" scale="1 ${reflect} 1"/>
        </geometry>
      </collision>
    </link>

    <joint name="${name}_${side}_7_joint" type="revolute">
      <parent link="${name}_${side}_6_link" />
      <child link="${name}_${side}_7_link" />
      <origin xyz="0.0 0.0 0.0"
                rpy="${0.0 * deg_to_rad} ${0.0 * deg_to_rad} ${0.0 * deg_to_rad}"/>
      <axis xyz="0 1 0" />
      <limit lower="${-39.0 * deg_to_rad}" upper="${39.0 * deg_to_rad}" effort="${wrist_3_max_effort}" velocity="${wrist_3_max_vel}"/>
      <dynamics friction="${wrist_friction}" damping="${wrist_damping}"/>
<!--       <safety_controller k_position="20"
                          k_velocity="20"
                          soft_lower_limit="${-40.00000 * deg_to_rad + eps_radians}"
                          soft_upper_limit="${40.00000 * deg_to_rad - eps_radians}" /> -->


    </joint>

    <gazebo reference="${name}_${side}_5_link">
      <mu1>0.9</mu1>
      <mu2>0.9</mu2>
    </gazebo>
    <gazebo reference="${name}_${side}_6_link">
      <mu1>0.9</mu1>
      <mu2>0.9</mu2>
    </gazebo>
    <gazebo reference="${name}_${side}_7_link">
      <mu1>0.9</mu1>
      <mu2>0.9</mu2>
      <material>Gazebo/FlatBlack</material>
    </gazebo>

    <gazebo reference="${name}_${side}_5_joint">
        <implicitSpringDamper>1</implicitSpringDamper>
    </gazebo>
    <gazebo reference="${name}_${side}_6_joint">
        <implicitSpringDamper>1</implicitSpringDamper>
    </gazebo>
    <gazebo reference="${name}_${side}_7_joint">
        <implicitSpringDamper>1</implicitSpringDamper>
        <provideFeedback>1</provideFeedback>
    </gazebo>

    <!-- extensions -->
    <xacro:include filename="$(find talos_description)/urdf/arm/${side}_wrist.transmissions.urdf.xacro" />
  </xacro:macro>

</robot>
